import unittest
from unittest.mock import patch, MagicMock
import concurrent.futures
import time

# Here is your actual generate_text function
def generate_text(prompt):
    max_attempts = 5
    with concurrent.futures.ThreadPoolExecutor() as executor:
        for attempt in range(max_attempts):
            future = executor.submit(api_call, prompt)
            try:
                completion = future.result(timeout=120)  # timeout after 120 seconds
                return completion["choices"][0]["message"]["content"]
            except concurrent.futures.TimeoutError:
                print("Timeout occurred, retrying...")
            except Exception as e:
                print(f"Error occurred: {e}. Retrying...")
            time.sleep(1)
    print(f"Failed after {max_attempts} attempts.")

# We'll mock this function for our tests
def api_call(prompt):
    pass  # In reality, this function would make the API call and return a response


class TestGenerateText(unittest.TestCase):
    @patch('__main__.api_call', return_value={"choices": [{"message": {"content": "test"}}]})
    def test_generate_text_success(self, api_call):
        # Test that the function works when api_call does not raise any exceptions
        self.assertEqual(generate_text('prompt'), 'test')
        api_call.assert_called_once()

    @patch('__main__.api_call', side_effect=concurrent.futures.TimeoutError)
    def test_generate_text_timeout(self, api_call):
        # Test that the function correctly retries when api_call raises a TimeoutError
        with self.assertRaises(concurrent.futures.TimeoutError):
            generate_text('prompt')
        self.assertEqual(api_call.call_count, 5)  # It should have tried 5 times


if __name__ == "__main__":
    unittest.main()
